Internal Server Error: /checkout/
Traceback (most recent call last):
  File "/workspace/.pip-modules/lib/python3.12/site-packages/django/core/handlers/exception.py", line 55, in inner
    response = get_response(request)
               ^^^^^^^^^^^^^^^^^^^^^
  File "/workspace/.pip-modules/lib/python3.12/site-packages/django/core/handlers/base.py", line 197, in _get_response
    response = wrapped_callback(request, *callback_args, **callback_kwargs)
               ^^^^^^^^^^^^^^^^^^^^^^^^^^^^^^^^^^^^^^^^^^^^^^^^^^^^^^^^^^^^
  File "/workspace/Giggles-Grins/checkout/views.py", line 82, in checkout
    order_line_item.save()
  File "/workspace/Giggles-Grins/checkout/models.py", line 134, in save
    self.order.update_total()
  File "/workspace/Giggles-Grins/checkout/models.py", line 65, in update_total
    post_save.disconnect(update_on_save, sender=OrderLineItem)
    ^^^^^^^^^
NameError: name 'post_save' is not defined
"POST /checkout/ HTTP/1.1" 500 90450
Internal Server Error: /checkout/
Traceback (most recent call last):
  File "/workspace/.pip-modules/lib/python3.12/site-packages/django/core/handlers/exception.py", line 55, in inner
    response = get_response(request)
               ^^^^^^^^^^^^^^^^^^^^^
  File "/workspace/.pip-modules/lib/python3.12/site-packages/django/core/handlers/base.py", line 197, in _get_response
    response = wrapped_callback(request, *callback_args, **callback_kwargs)
               ^^^^^^^^^^^^^^^^^^^^^^^^^^^^^^^^^^^^^^^^^^^^^^^^^^^^^^^^^^^^
  File "/workspace/Giggles-Grins/checkout/views.py", line 82, in checkout
    order_line_item.save()
  File "/workspace/Giggles-Grins/checkout/models.py", line 136, in save
    self.order.update_total()
  File "/workspace/Giggles-Grins/checkout/models.py", line 67, in update_total
    post_save.disconnect(update_on_save, sender=OrderLineItem)
                         ^^^^^^^^^^^^^^
NameError: name 'update_on_save' is not defined
"POST /checkout/ HTTP/1.1" 500 90580
Internal Server Error: /checkout/
Traceback (most recent call last):
  File "/workspace/.pip-modules/lib/python3.12/site-packages/django/core/handlers/exception.py", line 55, in inner
    response = get_response(request)
               ^^^^^^^^^^^^^^^^^^^^^
  File "/workspace/.pip-modules/lib/python3.12/site-packages/django/core/handlers/base.py", line 197, in _get_response
    response = wrapped_callback(request, *callback_args, **callback_kwargs)
               ^^^^^^^^^^^^^^^^^^^^^^^^^^^^^^^^^^^^^^^^^^^^^^^^^^^^^^^^^^^^
  File "/workspace/Giggles-Grins/checkout/views.py", line 82, in checkout
    order_line_item.save()
  File "/workspace/Giggles-Grins/checkout/models.py", line 133, in save
    super().save(*args, **kwargs)
  File "/workspace/.pip-modules/lib/python3.12/site-packages/django/db/models/base.py", line 814, in save
    self.save_base(
  File "/workspace/.pip-modules/lib/python3.12/site-packages/django/db/models/base.py", line 892, in save_base
    post_save.send(
  File "/workspace/.pip-modules/lib/python3.12/site-packages/django/dispatch/dispatcher.py", line 177, in send
    (receiver, receiver(signal=self, sender=sender, **named))
               ^^^^^^^^^^^^^^^^^^^^^^^^^^^^^^^^^^^^^^^^^^^^^
  File "/workspace/Giggles-Grins/checkout/signals.py", line 12, in update_on_save
    instance.order.update_total()
  File "/workspace/Giggles-Grins/checkout/models.py", line 67, in update_total
    post_save.disconnect(update_on_save, sender=OrderLineItem)
                         ^^^^^^^^^^^^^^
NameError: name 'update_on_save' is not defined
"POST /checkout/ HTTP/1.1" 500 109911
Internal Server Error: /products/
Traceback (most recent call last):
  File "C:\Users\HP\Documents\vscode-projects\Giggles-Grins\.venv\Lib\site-packages\django\db\backends\base\base.py", line 289, in ensure_connection
    self.connect()
  File "C:\Users\HP\Documents\vscode-projects\Giggles-Grins\.venv\Lib\site-packages\django\utils\asyncio.py", line 26, in inner
    return func(*args, **kwargs)
           ^^^^^^^^^^^^^^^^^^^^^
  File "C:\Users\HP\Documents\vscode-projects\Giggles-Grins\.venv\Lib\site-packages\django\db\backends\base\base.py", line 270, in connect
    self.connection = self.get_new_connection(conn_params)
                      ^^^^^^^^^^^^^^^^^^^^^^^^^^^^^^^^^^^^
  File "C:\Users\HP\Documents\vscode-projects\Giggles-Grins\.venv\Lib\site-packages\django\utils\asyncio.py", line 26, in inner
    return func(*args, **kwargs)
           ^^^^^^^^^^^^^^^^^^^^^
  File "C:\Users\HP\Documents\vscode-projects\Giggles-Grins\.venv\Lib\site-packages\django\db\backends\postgresql\base.py", line 269, in get_new_connection
    connection = self.Database.connect(**conn_params)
                 ^^^^^^^^^^^^^^^^^^^^^^^^^^^^^^^^^^^^
  File "C:\Users\HP\Documents\vscode-projects\Giggles-Grins\.venv\Lib\site-packages\psycopg2\__init__.py", line 122, in connect
    conn = _connect(dsn, connection_factory=connection_factory, **kwasync)
           ^^^^^^^^^^^^^^^^^^^^^^^^^^^^^^^^^^^^^^^^^^^^^^^^^^^^^^^^^^^^^^^
psycopg2.OperationalError: could not translate host name "ep-bold-meadow-a2a7smtq.eu-central-1.aws.neon.tech" to address: No such host is known. 


The above exception was the direct cause of the following exception:

Traceback (most recent call last):
  File "C:\Users\HP\Documents\vscode-projects\Giggles-Grins\.venv\Lib\site-packages\django\core\handlers\exception.py", line 55, in inner
    response = get_response(request)
               ^^^^^^^^^^^^^^^^^^^^^
  File "C:\Users\HP\Documents\vscode-projects\Giggles-Grins\.venv\Lib\site-packages\django\core\handlers\base.py", line 197, in _get_response
    response = wrapped_callback(request, *callback_args, **callback_kwargs)
               ^^^^^^^^^^^^^^^^^^^^^^^^^^^^^^^^^^^^^^^^^^^^^^^^^^^^^^^^^^^^
  File "C:\Users\HP\Documents\vscode-projects\Giggles-Grins\products\views.py", line 46, in all_products
    print(f"Products after category filter: {products.count()}")
                                             ^^^^^^^^^^^^^^^^
  File "C:\Users\HP\Documents\vscode-projects\Giggles-Grins\.venv\Lib\site-packages\django\db\models\query.py", line 608, in count
    return self.query.get_count(using=self.db)
           ^^^^^^^^^^^^^^^^^^^^^^^^^^^^^^^^^^^
  File "C:\Users\HP\Documents\vscode-projects\Giggles-Grins\.venv\Lib\site-packages\django\db\models\sql\query.py", line 536, in get_count
    return obj.get_aggregation(using, {"__count": Count("*")})["__count"]
           ^^^^^^^^^^^^^^^^^^^^^^^^^^^^^^^^^^^^^^^^^^^^^^^^^^^
  File "C:\Users\HP\Documents\vscode-projects\Giggles-Grins\.venv\Lib\site-packages\django\db\models\sql\query.py", line 522, in get_aggregation
    result = compiler.execute_sql(SINGLE)
             ^^^^^^^^^^^^^^^^^^^^^^^^^^^^
  File "C:\Users\HP\Documents\vscode-projects\Giggles-Grins\.venv\Lib\site-packages\django\db\models\sql\compiler.py", line 1558, in execute_sql
    cursor = self.connection.cursor()
             ^^^^^^^^^^^^^^^^^^^^^^^^
  File "C:\Users\HP\Documents\vscode-projects\Giggles-Grins\.venv\Lib\site-packages\django\utils\asyncio.py", line 26, in inner
    return func(*args, **kwargs)
           ^^^^^^^^^^^^^^^^^^^^^
  File "C:\Users\HP\Documents\vscode-projects\Giggles-Grins\.venv\Lib\site-packages\django\db\backends\base\base.py", line 330, in cursor
    return self._cursor()
           ^^^^^^^^^^^^^^
  File "C:\Users\HP\Documents\vscode-projects\Giggles-Grins\.venv\Lib\site-packages\django\db\backends\base\base.py", line 306, in _cursor
    self.ensure_connection()
  File "C:\Users\HP\Documents\vscode-projects\Giggles-Grins\.venv\Lib\site-packages\django\utils\asyncio.py", line 26, in inner
    return func(*args, **kwargs)
           ^^^^^^^^^^^^^^^^^^^^^
  File "C:\Users\HP\Documents\vscode-projects\Giggles-Grins\.venv\Lib\site-packages\django\db\backends\base\base.py", line 288, in ensure_connection
    with self.wrap_database_errors:
         ^^^^^^^^^^^^^^^^^^^^^^^^^
  File "C:\Users\HP\Documents\vscode-projects\Giggles-Grins\.venv\Lib\site-packages\django\db\utils.py", line 91, in __exit__
    raise dj_exc_value.with_traceback(traceback) from exc_value
  File "C:\Users\HP\Documents\vscode-projects\Giggles-Grins\.venv\Lib\site-packages\django\db\backends\base\base.py", line 289, in ensure_connection
    self.connect()
  File "C:\Users\HP\Documents\vscode-projects\Giggles-Grins\.venv\Lib\site-packages\django\utils\asyncio.py", line 26, in inner
    return func(*args, **kwargs)
           ^^^^^^^^^^^^^^^^^^^^^
  File "C:\Users\HP\Documents\vscode-projects\Giggles-Grins\.venv\Lib\site-packages\django\db\backends\base\base.py", line 270, in connect
    self.connection = self.get_new_connection(conn_params)
                      ^^^^^^^^^^^^^^^^^^^^^^^^^^^^^^^^^^^^
  File "C:\Users\HP\Documents\vscode-projects\Giggles-Grins\.venv\Lib\site-packages\django\utils\asyncio.py", line 26, in inner
    return func(*args, **kwargs)
           ^^^^^^^^^^^^^^^^^^^^^
  File "C:\Users\HP\Documents\vscode-projects\Giggles-Grins\.venv\Lib\site-packages\django\db\backends\postgresql\base.py", line 269, in get_new_connection
    connection = self.Database.connect(**conn_params)
                 ^^^^^^^^^^^^^^^^^^^^^^^^^^^^^^^^^^^^
  File "C:\Users\HP\Documents\vscode-projects\Giggles-Grins\.venv\Lib\site-packages\psycopg2\__init__.py", line 122, in connect
    conn = _connect(dsn, connection_factory=connection_factory, **kwasync)
           ^^^^^^^^^^^^^^^^^^^^^^^^^^^^^^^^^^^^^^^^^^^^^^^^^^^^^^^^^^^^^^^
django.db.utils.OperationalError: could not translate host name "ep-bold-meadow-a2a7smtq.eu-central-1.aws.neon.tech" to address: No such host is known. 

"GET /products/?category=Girl%20Fashion&subcategory=Dresses HTTP/1.1" 500 145
Internal Server Error: /contact/
Traceback (most recent call last):
  File "C:\Users\HP\Documents\vscode-projects\Giggles-Grins\.venv\Lib\site-packages\django\core\handlers\exception.py", line 55, in inner
    response = get_response(request)
               ^^^^^^^^^^^^^^^^^^^^^
  File "C:\Users\HP\Documents\vscode-projects\Giggles-Grins\.venv\Lib\site-packages\django\core\handlers\base.py", line 197, in _get_response
    response = wrapped_callback(request, *callback_args, **callback_kwargs)
               ^^^^^^^^^^^^^^^^^^^^^^^^^^^^^^^^^^^^^^^^^^^^^^^^^^^^^^^^^^^^
  File "C:\Users\HP\Documents\vscode-projects\Giggles-Grins\home\views.py", line 33, in contact
    return render(request, 'contact.html', {'form': form})
           ^^^^^^^^^^^^^^^^^^^^^^^^^^^^^^^^^^^^^^^^^^^^^^^
  File "C:\Users\HP\Documents\vscode-projects\Giggles-Grins\.venv\Lib\site-packages\django\shortcuts.py", line 24, in render
    content = loader.render_to_string(template_name, context, request, using=using)
              ^^^^^^^^^^^^^^^^^^^^^^^^^^^^^^^^^^^^^^^^^^^^^^^^^^^^^^^^^^^^^^^^^^^^^
  File "C:\Users\HP\Documents\vscode-projects\Giggles-Grins\.venv\Lib\site-packages\django\template\loader.py", line 61, in render_to_string
    template = get_template(template_name, using=using)
               ^^^^^^^^^^^^^^^^^^^^^^^^^^^^^^^^^^^^^^^^
  File "C:\Users\HP\Documents\vscode-projects\Giggles-Grins\.venv\Lib\site-packages\django\template\loader.py", line 19, in get_template
    raise TemplateDoesNotExist(template_name, chain=chain)
django.template.exceptions.TemplateDoesNotExist: contact.html
"GET /contact/ HTTP/1.1" 500 91918
Internal Server Error: /contact/
Traceback (most recent call last):
  File "C:\Users\HP\Documents\vscode-projects\Giggles-Grins\.venv\Lib\site-packages\django\core\handlers\exception.py", line 55, in inner
    response = get_response(request)
               ^^^^^^^^^^^^^^^^^^^^^
  File "C:\Users\HP\Documents\vscode-projects\Giggles-Grins\.venv\Lib\site-packages\django\core\handlers\base.py", line 197, in _get_response
    response = wrapped_callback(request, *callback_args, **callback_kwargs)
               ^^^^^^^^^^^^^^^^^^^^^^^^^^^^^^^^^^^^^^^^^^^^^^^^^^^^^^^^^^^^
  File "C:\Users\HP\Documents\vscode-projects\Giggles-Grins\home\views.py", line 33, in contact
    return render(request, 'contact.html', {'form': form})
           ^^^^^^^^^^^^^^^^^^^^^^^^^^^^^^^^^^^^^^^^^^^^^^^
  File "C:\Users\HP\Documents\vscode-projects\Giggles-Grins\.venv\Lib\site-packages\django\shortcuts.py", line 24, in render
    content = loader.render_to_string(template_name, context, request, using=using)
              ^^^^^^^^^^^^^^^^^^^^^^^^^^^^^^^^^^^^^^^^^^^^^^^^^^^^^^^^^^^^^^^^^^^^^
  File "C:\Users\HP\Documents\vscode-projects\Giggles-Grins\.venv\Lib\site-packages\django\template\loader.py", line 61, in render_to_string
    template = get_template(template_name, using=using)
               ^^^^^^^^^^^^^^^^^^^^^^^^^^^^^^^^^^^^^^^^
  File "C:\Users\HP\Documents\vscode-projects\Giggles-Grins\.venv\Lib\site-packages\django\template\loader.py", line 19, in get_template
    raise TemplateDoesNotExist(template_name, chain=chain)
django.template.exceptions.TemplateDoesNotExist: contact.html
"GET /contact/ HTTP/1.1" 500 92416
Internal Server Error: /contact/
Traceback (most recent call last):
  File "C:\Users\HP\Documents\vscode-projects\Giggles-Grins\.venv\Lib\site-packages\django\core\handlers\exception.py", line 55, in inner
    response = get_response(request)
               ^^^^^^^^^^^^^^^^^^^^^
  File "C:\Users\HP\Documents\vscode-projects\Giggles-Grins\.venv\Lib\site-packages\django\core\handlers\base.py", line 197, in _get_response
    response = wrapped_callback(request, *callback_args, **callback_kwargs)
               ^^^^^^^^^^^^^^^^^^^^^^^^^^^^^^^^^^^^^^^^^^^^^^^^^^^^^^^^^^^^
  File "C:\Users\HP\Documents\vscode-projects\Giggles-Grins\home\views.py", line 33, in contact
    return render(request, 'contact.html', {'form': form})
           ^^^^^^^^^^^^^^^^^^^^^^^^^^^^^^^^^^^^^^^^^^^^^^^
  File "C:\Users\HP\Documents\vscode-projects\Giggles-Grins\.venv\Lib\site-packages\django\shortcuts.py", line 24, in render
    content = loader.render_to_string(template_name, context, request, using=using)
              ^^^^^^^^^^^^^^^^^^^^^^^^^^^^^^^^^^^^^^^^^^^^^^^^^^^^^^^^^^^^^^^^^^^^^
  File "C:\Users\HP\Documents\vscode-projects\Giggles-Grins\.venv\Lib\site-packages\django\template\loader.py", line 61, in render_to_string
    template = get_template(template_name, using=using)
               ^^^^^^^^^^^^^^^^^^^^^^^^^^^^^^^^^^^^^^^^
  File "C:\Users\HP\Documents\vscode-projects\Giggles-Grins\.venv\Lib\site-packages\django\template\loader.py", line 19, in get_template
    raise TemplateDoesNotExist(template_name, chain=chain)
django.template.exceptions.TemplateDoesNotExist: contact.html
"GET /contact/ HTTP/1.1" 500 92416
Internal Server Error: /contact/
Traceback (most recent call last):
  File "C:\Users\HP\Documents\vscode-projects\Giggles-Grins\.venv\Lib\site-packages\django\core\handlers\exception.py", line 55, in inner
    response = get_response(request)
               ^^^^^^^^^^^^^^^^^^^^^
  File "C:\Users\HP\Documents\vscode-projects\Giggles-Grins\.venv\Lib\site-packages\django\core\handlers\base.py", line 197, in _get_response
    response = wrapped_callback(request, *callback_args, **callback_kwargs)
               ^^^^^^^^^^^^^^^^^^^^^^^^^^^^^^^^^^^^^^^^^^^^^^^^^^^^^^^^^^^^
  File "C:\Users\HP\Documents\vscode-projects\Giggles-Grins\home\views.py", line 33, in contact
    return render(request, 'contact.html', {'form': form})
           ^^^^^^^^^^^^^^^^^^^^^^^^^^^^^^^^^^^^^^^^^^^^^^^
  File "C:\Users\HP\Documents\vscode-projects\Giggles-Grins\.venv\Lib\site-packages\django\shortcuts.py", line 24, in render
    content = loader.render_to_string(template_name, context, request, using=using)
              ^^^^^^^^^^^^^^^^^^^^^^^^^^^^^^^^^^^^^^^^^^^^^^^^^^^^^^^^^^^^^^^^^^^^^
  File "C:\Users\HP\Documents\vscode-projects\Giggles-Grins\.venv\Lib\site-packages\django\template\loader.py", line 61, in render_to_string
    template = get_template(template_name, using=using)
               ^^^^^^^^^^^^^^^^^^^^^^^^^^^^^^^^^^^^^^^^
  File "C:\Users\HP\Documents\vscode-projects\Giggles-Grins\.venv\Lib\site-packages\django\template\loader.py", line 19, in get_template
    raise TemplateDoesNotExist(template_name, chain=chain)
django.template.exceptions.TemplateDoesNotExist: contact.html
"GET /contact/ HTTP/1.1" 500 92416
Internal Server Error: /contact/
Traceback (most recent call last):
  File "C:\Users\HP\Documents\vscode-projects\Giggles-Grins\.venv\Lib\site-packages\django\core\handlers\exception.py", line 55, in inner
    response = get_response(request)
               ^^^^^^^^^^^^^^^^^^^^^
  File "C:\Users\HP\Documents\vscode-projects\Giggles-Grins\.venv\Lib\site-packages\django\core\handlers\base.py", line 197, in _get_response
    response = wrapped_callback(request, *callback_args, **callback_kwargs)
               ^^^^^^^^^^^^^^^^^^^^^^^^^^^^^^^^^^^^^^^^^^^^^^^^^^^^^^^^^^^^
  File "C:\Users\HP\Documents\vscode-projects\Giggles-Grins\home\views.py", line 33, in contact
    return render(request, 'contact.html', {'form': form})
           ^^^^^^^^^^^^^^^^^^^^^^^^^^^^^^^^^^^^^^^^^^^^^^^
  File "C:\Users\HP\Documents\vscode-projects\Giggles-Grins\.venv\Lib\site-packages\django\shortcuts.py", line 24, in render
    content = loader.render_to_string(template_name, context, request, using=using)
              ^^^^^^^^^^^^^^^^^^^^^^^^^^^^^^^^^^^^^^^^^^^^^^^^^^^^^^^^^^^^^^^^^^^^^
  File "C:\Users\HP\Documents\vscode-projects\Giggles-Grins\.venv\Lib\site-packages\django\template\loader.py", line 61, in render_to_string
    template = get_template(template_name, using=using)
               ^^^^^^^^^^^^^^^^^^^^^^^^^^^^^^^^^^^^^^^^
  File "C:\Users\HP\Documents\vscode-projects\Giggles-Grins\.venv\Lib\site-packages\django\template\loader.py", line 19, in get_template
    raise TemplateDoesNotExist(template_name, chain=chain)
django.template.exceptions.TemplateDoesNotExist: contact.html
"GET /contact/ HTTP/1.1" 500 92393
Internal Server Error: /contact/contact/
Traceback (most recent call last):
  File "C:\Users\HP\Documents\vscode-projects\Giggles-Grins\.venv\Lib\site-packages\django\core\handlers\exception.py", line 55, in inner
    response = get_response(request)
               ^^^^^^^^^^^^^^^^^^^^^
  File "C:\Users\HP\Documents\vscode-projects\Giggles-Grins\.venv\Lib\site-packages\django\core\handlers\base.py", line 197, in _get_response
    response = wrapped_callback(request, *callback_args, **callback_kwargs)
               ^^^^^^^^^^^^^^^^^^^^^^^^^^^^^^^^^^^^^^^^^^^^^^^^^^^^^^^^^^^^
  File "C:\Users\HP\Documents\vscode-projects\Giggles-Grins\custom_features\views.py", line 18, in contact_form_view
    return render(request, 'contact_form.html', {'form': form})
           ^^^^^^^^^^^^^^^^^^^^^^^^^^^^^^^^^^^^^^^^^^^^^^^^^^^^
  File "C:\Users\HP\Documents\vscode-projects\Giggles-Grins\.venv\Lib\site-packages\django\shortcuts.py", line 24, in render
    content = loader.render_to_string(template_name, context, request, using=using)
              ^^^^^^^^^^^^^^^^^^^^^^^^^^^^^^^^^^^^^^^^^^^^^^^^^^^^^^^^^^^^^^^^^^^^^
  File "C:\Users\HP\Documents\vscode-projects\Giggles-Grins\.venv\Lib\site-packages\django\template\loader.py", line 61, in render_to_string
    template = get_template(template_name, using=using)
               ^^^^^^^^^^^^^^^^^^^^^^^^^^^^^^^^^^^^^^^^
  File "C:\Users\HP\Documents\vscode-projects\Giggles-Grins\.venv\Lib\site-packages\django\template\loader.py", line 19, in get_template
    raise TemplateDoesNotExist(template_name, chain=chain)
django.template.exceptions.TemplateDoesNotExist: contact_form.html
"GET /contact/contact/ HTTP/1.1" 500 93053
<<<<<<< HEAD
Internal Server Error: /contact/contact/
Traceback (most recent call last):
  File "C:\Users\HP\Documents\vscode-projects\Giggles-Grins\.venv\Lib\site-packages\django\core\handlers\exception.py", line 55, in inner
    response = get_response(request)
               ^^^^^^^^^^^^^^^^^^^^^
  File "C:\Users\HP\Documents\vscode-projects\Giggles-Grins\.venv\Lib\site-packages\django\core\handlers\base.py", line 197, in _get_response
    response = wrapped_callback(request, *callback_args, **callback_kwargs)
               ^^^^^^^^^^^^^^^^^^^^^^^^^^^^^^^^^^^^^^^^^^^^^^^^^^^^^^^^^^^^
  File "C:\Users\HP\Documents\vscode-projects\Giggles-Grins\custom_features\views.py", line 16, in contact_form_view
    return redirect('contact_success')
           ^^^^^^^^^^^^^^^^^^^^^^^^^^^
  File "C:\Users\HP\Documents\vscode-projects\Giggles-Grins\.venv\Lib\site-packages\django\shortcuts.py", line 48, in redirect
    return redirect_class(resolve_url(to, *args, **kwargs))
                          ^^^^^^^^^^^^^^^^^^^^^^^^^^^^^^^^
  File "C:\Users\HP\Documents\vscode-projects\Giggles-Grins\.venv\Lib\site-packages\django\shortcuts.py", line 145, in resolve_url
    return reverse(to, args=args, kwargs=kwargs)
           ^^^^^^^^^^^^^^^^^^^^^^^^^^^^^^^^^^^^^
  File "C:\Users\HP\Documents\vscode-projects\Giggles-Grins\.venv\Lib\site-packages\django\urls\base.py", line 88, in reverse
    return resolver._reverse_with_prefix(view, prefix, *args, **kwargs)
           ^^^^^^^^^^^^^^^^^^^^^^^^^^^^^^^^^^^^^^^^^^^^^^^^^^^^^^^^^^^^
  File "C:\Users\HP\Documents\vscode-projects\Giggles-Grins\.venv\Lib\site-packages\django\urls\resolvers.py", line 828, in _reverse_with_prefix
    raise NoReverseMatch(msg)
django.urls.exceptions.NoReverseMatch: Reverse for 'contact_success' not found. 'contact_success' is not a valid view function or pattern name.
"POST /contact/contact/ HTTP/1.1" 500 145
Internal Server Error: /contact/contact/
Traceback (most recent call last):
  File "C:\Users\HP\Documents\vscode-projects\Giggles-Grins\.venv\Lib\site-packages\django\core\handlers\exception.py", line 55, in inner
    response = get_response(request)
               ^^^^^^^^^^^^^^^^^^^^^
  File "C:\Users\HP\Documents\vscode-projects\Giggles-Grins\.venv\Lib\site-packages\django\core\handlers\base.py", line 197, in _get_response
    response = wrapped_callback(request, *callback_args, **callback_kwargs)
               ^^^^^^^^^^^^^^^^^^^^^^^^^^^^^^^^^^^^^^^^^^^^^^^^^^^^^^^^^^^^
  File "C:\Users\HP\Documents\vscode-projects\Giggles-Grins\custom_features\views.py", line 16, in contact_form_view
    return redirect('contact_success')
           ^^^^^^^^^^^^^^^^^^^^^^^^^^^
  File "C:\Users\HP\Documents\vscode-projects\Giggles-Grins\.venv\Lib\site-packages\django\shortcuts.py", line 48, in redirect
    return redirect_class(resolve_url(to, *args, **kwargs))
                          ^^^^^^^^^^^^^^^^^^^^^^^^^^^^^^^^
  File "C:\Users\HP\Documents\vscode-projects\Giggles-Grins\.venv\Lib\site-packages\django\shortcuts.py", line 145, in resolve_url
    return reverse(to, args=args, kwargs=kwargs)
           ^^^^^^^^^^^^^^^^^^^^^^^^^^^^^^^^^^^^^
  File "C:\Users\HP\Documents\vscode-projects\Giggles-Grins\.venv\Lib\site-packages\django\urls\base.py", line 88, in reverse
    return resolver._reverse_with_prefix(view, prefix, *args, **kwargs)
           ^^^^^^^^^^^^^^^^^^^^^^^^^^^^^^^^^^^^^^^^^^^^^^^^^^^^^^^^^^^^
  File "C:\Users\HP\Documents\vscode-projects\Giggles-Grins\.venv\Lib\site-packages\django\urls\resolvers.py", line 828, in _reverse_with_prefix
    raise NoReverseMatch(msg)
django.urls.exceptions.NoReverseMatch: Reverse for 'contact_success' not found. 'contact_success' is not a valid view function or pattern name.
"POST /contact/contact/ HTTP/1.1" 500 145
Internal Server Error: /contact/contact/
Traceback (most recent call last):
  File "C:\Users\HP\Documents\vscode-projects\Giggles-Grins\.venv\Lib\site-packages\django\core\handlers\exception.py", line 55, in inner
    response = get_response(request)
               ^^^^^^^^^^^^^^^^^^^^^
  File "C:\Users\HP\Documents\vscode-projects\Giggles-Grins\.venv\Lib\site-packages\django\core\handlers\base.py", line 197, in _get_response
    response = wrapped_callback(request, *callback_args, **callback_kwargs)
               ^^^^^^^^^^^^^^^^^^^^^^^^^^^^^^^^^^^^^^^^^^^^^^^^^^^^^^^^^^^^
  File "C:\Users\HP\Documents\vscode-projects\Giggles-Grins\custom_features\views.py", line 20, in contact_form_view
    send_mail(
  File "C:\Users\HP\Documents\vscode-projects\Giggles-Grins\.venv\Lib\site-packages\django\core\mail\__init__.py", line 87, in send_mail
    return mail.send()
           ^^^^^^^^^^^
  File "C:\Users\HP\Documents\vscode-projects\Giggles-Grins\.venv\Lib\site-packages\django\core\mail\message.py", line 298, in send
    return self.get_connection(fail_silently).send_messages([self])
           ^^^^^^^^^^^^^^^^^^^^^^^^^^^^^^^^^^^^^^^^^^^^^^^^^^^^^^^^
  File "C:\Users\HP\Documents\vscode-projects\Giggles-Grins\.venv\Lib\site-packages\django\core\mail\backends\smtp.py", line 127, in send_messages
    new_conn_created = self.open()
                       ^^^^^^^^^^^
  File "C:\Users\HP\Documents\vscode-projects\Giggles-Grins\.venv\Lib\site-packages\django\core\mail\backends\smtp.py", line 94, in open
    self.connection.login(self.username, self.password)
  File "C:\Users\HP\AppData\Local\Programs\Python\Python312\Lib\smtplib.py", line 750, in login
    raise last_exception
  File "C:\Users\HP\AppData\Local\Programs\Python\Python312\Lib\smtplib.py", line 739, in login
    (code, resp) = self.auth(
                   ^^^^^^^^^^
  File "C:\Users\HP\AppData\Local\Programs\Python\Python312\Lib\smtplib.py", line 662, in auth
    raise SMTPAuthenticationError(code, resp)
smtplib.SMTPAuthenticationError: (535, b'5.7.8 Username and Password not accepted. For more information, go to\n5.7.8  https://support.google.com/mail/?p=BadCredentials ffacd0b85a97d-395cb7eb92csm15425491f8f.91 - gsmtp')
"POST /contact/contact/ HTTP/1.1" 500 110746
=======
>>>>>>> b5f902bcadebe8c9b07e74c8effbb7d72511f367
